Workbook

Sheet Convention
A1: Convention de saisie — Suivi de présence consultants
A3: Ce fichier sert à suivre la présence des consultants au bureau et à mesurer notre OKR (objectif : 2 jours/mois minimum par consultant).
A5: Symboles à utiliser dans les onglets de saisie mensuelle
A6: Symbole | B6: Signification | C6: Impact sur le calcul
A7: 1 | B7: Présence au bureau | C7: Compte dans le total de présences du consultant
A8: IC | B8: Présence pendant une période d'intercontrat | C8: Compte comme une présence dans le total OKR. Permet de visualiser la période d'intercontrat.
A9: (vide) | B9: Absence par défaut (pas venu, en mission, télétravail, congés courts) | C9: Compte comme "non présent" — sous l'objectif si pas assez de "1"
A10: M | B10: Absence longue : congé maternité/paternité, parental, maladie longue, sabbatique | C10: Le consultant est exclu du calcul d'atteinte OKR pour ce mois
A11: X | B11: Date d'un événement (ligne XO Day, XO Product Day, Séminaire) | C11: Permet d'overlay l'événement sur les graphiques
A13: Comment utiliser le fichier
A14: 1. Onglet "Référentiel" : ajoute/retire les consultants au fil des arrivées et départs.
A15: 2. Onglet "Événements" : déclare en amont les XO Days, XO Product Days et séminaires prévus.
A16: 3. Onglets "Saisie YYYY-MM" : saisie quotidienne des présences (1 dans la cellule). Crée un nouvel onglet par mois.
A17: 4. Onglet "Log" : se met à jour automatiquement, pas de saisie manuelle. C'est la source pour le dashboard.
A18: 5. Onglets "Synthèse" : KPI calculés automatiquement.
A21: Note importante
A22: Ce fichier est un fichier source. Les données calculées dans les onglets Log et Synthèse alimentent un dashboard externe (web). Ne pas modifier les formules de ces onglets.
A24: Symboles à utiliser dans l'onglet Formations_Participations
A25: Symbole | B25: Signification | C25: Impact sur le calcul
A26: F | B26: Formateur(rice) de la session | C26: Compte comme une animation dans le total du consultant (bleu)
A27: P | B27: Participant(e) présent(e) à la session | C27: Compte comme une participation dans le total du consultant (vert)
A28: (vide) | B28: Non concerné par la session | C28: Ne compte pas
A30: Conventions pour l'onglet Formations
A31: id_session | B31: Format F-YYYY-NNN. NNN incrément manuel, remis à 1 chaque année (ex. F-2026-001).
A32: date | B32: Date de la session, une session = un jour.
A33: thématique | B33: Libellé court de la session, texte libre.
A34: formateur | B34: Nom du/des formateur(s). Plusieurs noms séparés par virgule en cas de co-animation.
A35: lien_support | B35: URL du support de session (Notion en général). Optionnel.
A37: Règle importante
A38: Les consultants dans Formations_Participations doivent rester dans le même ordre que dans les onglets Saisie YYYY-MM. Toute réorganisation (ajout, retrait, tri) doit être faite simultanément dans les deux familles d'onglets pour préserver la cohérence (et la future vue consultant consolidée).
A40: Cycle de vie des consultants (Référentiel)
A41: Règle absolue | B41: Ne jamais supprimer une ligne consultant. Quand un consultant part, remplir Date de sortie ; sa ligne reste en place dans Référentiel et dans toutes les matrices, ce qui préserve son historique.
A42: Arrivée | B42: Ajouter au Référentiel avec Date d'entrée. Ajouter une ligne consultant dans les matrices Saisie YYYY-MM (présent et à venir) et Formations_Participations.
A43: Départ | B43: Remplir Date de sortie dans le Référentiel. Ne pas toucher aux matrices.
A45: Saisie d'un formateur
A46: Onglet Formations | B46: Choisis le nom dans la liste déroulante de la colonne formateur. Pour co-animation, sépare plusieurs noms par une virgule.
A47: Matrice Formations_Participations | B47: Basculer le P du formateur en F à la colonne de la session concernée, pour que son animation soit comptée dans son total d'engagement.
A49: Module Feedback Formation
A50: Onglet Formation_Feedbacks | B50: Une ligne par réponse individuelle. Format long. L'id_session fait le lien avec l'onglet Formations. Pas de modération : chaque feedback est visible côté dashboard.
A51: Workflow d'import | B51: Après chaque session : exporter le CSV depuis Google Sheets lié au Form, renommer en feedback_F-YYYY-NNN.csv (id_session correspondant), déposer dans imports_feedbacks/, puis lancer python scripts/import_feedbacks.py. Le script est idempotent (re-runnable sans risque de doublons).
...

Sheet Référentiel
A1: Référentiel des consultants
A3: Consultant | B3: Date d'entrée | C3: Date de sortie | D3: Rôle
A4: Alexandre Dieulesaint
A5: Amandine Ziegler
A6: Anthony Mocaer
A7: Anthéa Delpuech
A8: Axel Charletoux
A9: Barnabé Melaine
A10: Bertrand Mignot | C10: 46178
A11: Calixte Bailly
A12: Caroline Hamoud | C12: 46218
A13: Esther Mussot | B13: 46082
A14: Eva Andrzejewski
A15: Florian Le Fur
A16: Florian Roudier
A17: François L'Hostis
A18: Félix Hantraye
A19: Geoffroy Debellabre
A20: Julien Calvao | C20: 46218
A21: Laureline Berthou
A22: Mathieu Ultsch
A23: Matthieu Le Corre
A24: Nacim Souni | C24: 46203
A25: Sandra Tang
A26: Simon Kerhyuel
A27: Théo Esposito
A28: Vincent Girard
A29: Zelal Aslan
A30: Anita Aladine | C30: 46053
A31: Camille Chansigaud | C31: 46022
A32: Emilien Rue | C32: 45777
A33: Gaetan Le Bail | C33: 45747
A34: Melchior R | C34: 45930
A35: Nicolas Renard | C35: 45960
A36: Jérémie Kieffer | B36: 45078 | D36: interne
A37: Agnes Bregeon | B37: 46174 | C37: 46218

Sheet Événements
A1: Calendrier des événements collectifs
A3: Date | B3: Type | C3: Libellé / Détail
A4: 46072 | B4: XO Product Day | C4: XO Product Day février
A5: 46107 | B5: XO Day | C5: XO Day mars
A6: 46135 | B6: XO Day | C6: XO Day avril
A7: 46148 | B7: XO Product Day | C7: XO Product Day mai
A8: 46170 | B8: XO Day | C8: XO Day mai
A9: 46182 | B9: XO Product Day | C9: XO Product Day juin
A10: 46192 | B10: XO Day | C10: XO Day juin

Sheet Saisie 2026-02
A1: Saisie présence — Février 2026
A3: Consultant | B3: 46055 | C3: 46056 | D3: 46057 | E3: 46058 | F3: 46059 | G3: 46062 | H3: 46063 | I3: 46064 | J3: 46065 | K3: 46066 | L3: 46069 | M3: 46070 | N3: 46071 | O3: 46072 | P3: 46073 | Q3: 46076 | R3: 46077 | S3: 46078 | T3: 46079 | U3: 46080 | V3: Total | W3: Statut OKR
A4: Eva Andrzejewski | H4: 1 | O4: 1 | R4: 1 | V4: =COUNTIF(B4:U4,1)+COUNTIF(B4:U4,"IC") -> 3 | W4: =IF(COUNTIF(B4:U4,"M")>0,"N/A absence longue",IF(V4>=2,"Atteint","Sous objectif")) -> Atteint
A5: Zelal Aslan | B5: M | C5: M | D5: M | E5: M | F5: M | G5: M | H5: M | I5: M | J5: M | K5: M | L5: M | M5: M | N5: M | O5: M | P5: M | Q5: M | R5: M | S5: M | T5: M | U5: M | V5: =COUNTIF(B5:U5,1)+COUNTIF(B5:U5,"IC") -> 0 | W5: =IF(COUNTIF(B5:U5,"M")>0,"N/A absence longue",IF(V5>=2,"Atteint","Sous objectif")) -> N/A absence longue
A6: Calixte Bailly | O6: 1 | V6: =COUNTIF(B6:U6,1)+COUNTIF(B6:U6,"IC") -> 1 | W6: =IF(COUNTIF(B6:U6,"M")>0,"N/A absence longue",IF(V6>=2,"Atteint","Sous objectif")) -> Sous objectif
A7: Laureline Berthou | C7: 1 | E7: 1 | J7: 1 | O7: 1 | R7: 1 | V7: =COUNTIF(B7:U7,1)+COUNTIF(B7:U7,"IC") -> 5 | W7: =IF(COUNTIF(B7:U7,"M")>0,"N/A absence longue",IF(V7>=2,"Atteint","Sous objectif")) -> Atteint
A8: Julien Calvao | B8: IC | C8: IC | E8: IC | H8: IC | I8: IC | J8: IC | L8: IC | M8: IC | Q8: IC | R8: IC | T8: IC | V8: =COUNTIF(B8:U8,1)+COUNTIF(B8:U8,"IC") -> 11 | W8: =IF(COUNTIF(B8:U8,"M")>0,"N/A absence longue",IF(V8>=2,"Atteint","Sous objectif")) -> Atteint
A9: Axel Charletoux | O9: 1 | V9: =COUNTIF(B9:U9,1)+COUNTIF(B9:U9,"IC") -> 1 | W9: =IF(COUNTIF(B9:U9,"M")>0,"N/A absence longue",IF(V9>=2,"Atteint","Sous objectif")) -> Sous objectif
A10: Matthieu Le Corre | C10: 1 | E10: 1 | H10: 1 | J10: 1 | M10: 1 | O10: 1 | R10: 1 | T10: 1 | V10: =COUNTIF(B10:U10,1)+COUNTIF(B10:U10,"IC") -> 8 | W10: =IF(COUNTIF(B10:U10,"M")>0,"N/A absence longue",IF(V10>=2,"Atteint","Sous objectif")) -> Atteint
A11: Geoffroy Debellabre | V11: =COUNTIF(B11:U11,1)+COUNTIF(B11:U11,"IC") -> 0 | W11: =IF(COUNTIF(B11:U11,"M")>0,"N/A absence longue",IF(V11>=2,"Atteint","Sous objectif")) -> Sous objectif
A12: Anthéa Delpuech | B12: 1 | C12: 1 | E12: 1 | R12: 1 | V12: =COUNTIF(B12:U12,1)+COUNTIF(B12:U12,"IC") -> 4 | W12: =IF(COUNTIF(B12:U12,"M")>0,"N/A absence longue",IF(V12>=2,"Atteint","Sous objectif")) -> Atteint
A13: Alexandre Dieulesaint | V13: =COUNTIF(B13:U13,1)+COUNTIF(B13:U13,"IC") -> 0 | W13: =IF(COUNTIF(B13:U13,"M")>0,"N/A absence longue",IF(V13>=2,"Atteint","Sous objectif")) -> Sous objectif
A14: Théo Esposito | C14: 1 | H14: 1 | R14: 1 | V14: =COUNTIF(B14:U14,1)+COUNTIF(B14:U14,"IC") -> 3 | W14: =IF(COUNTIF(B14:U14,"M")>0,"N/A absence longue",IF(V14>=2,"Atteint","Sous objectif")) -> Atteint
A15: Florian Le Fur | H15: 1 | O15: 1 | V15: =COUNTIF(B15:U15,1)+COUNTIF(B15:U15,"IC") -> 2 | W15: =IF(COUNTIF(B15:U15,"M")>0,"N/A absence longue",IF(V15>=2,"Atteint","Sous objectif")) -> Atteint
A16: Vincent Girard | H16: 1 | O16: 1 | R16: 1 | V16: =COUNTIF(B16:U16,1)+COUNTIF(B16:U16,"IC") -> 3 | W16: =IF(COUNTIF(B16:U16,"M")>0,"N/A absence longue",IF(V16>=2,"Atteint","Sous objectif")) -> Atteint
A17: Caroline Hamoud | V17: =COUNTIF(B17:U17,1)+COUNTIF(B17:U17,"IC") -> 0 | W17: =IF(COUNTIF(B17:U17,"M")>0,"N/A absence longue",IF(V17>=2,"Atteint","Sous objectif")) -> Sous objectif
A18: Félix Hantraye | H18: 1 | M18: 1 | O18: 1 | V18: =COUNTIF(B18:U18,1)+COUNTIF(B18:U18,"IC") -> 3 | W18: =IF(COUNTIF(B18:U18,"M")>0,"N/A absence longue",IF(V18>=2,"Atteint","Sous objectif")) -> Atteint
A19: Simon Kerhyuel | H19: 1 | V19: =COUNTIF(B19:U19,1)+COUNTIF(B19:U19,"IC") -> 1 | W19: =IF(COUNTIF(B19:U19,"M")>0,"N/A absence longue",IF(V19>=2,"Atteint","Sous objectif")) -> Sous objectif
A20: François L'Hostis | H20: 1 | O20: 1 | V20: =COUNTIF(B20:U20,1)+COUNTIF(B20:U20,"IC") -> 2 | W20: =IF(COUNTIF(B20:U20,"M")>0,"N/A absence longue",IF(V20>=2,"Atteint","Sous objectif")) -> Atteint
A21: Barnabé Melaine | H21: 1 | O21: 1 | V21: =COUNTIF(B21:U21,1)+COUNTIF(B21:U21,"IC") -> 2 | W21: =IF(COUNTIF(B21:U21,"M")>0,"N/A absence longue",IF(V21>=2,"Atteint","Sous objectif")) -> Atteint
A22: Bertrand Mignot | H22: 1 | O22: 1 | V22: =COUNTIF(B22:U22,1)+COUNTIF(B22:U22,"IC") -> 2 | W22: =IF(COUNTIF(B22:U22,"M")>0,"N/A absence longue",IF(V22>=2,"Atteint","Sous objectif")) -> Atteint
A23: Anthony Mocaer | R23: 1 | V23: =COUNTIF(B23:U23,1)+COUNTIF(B23:U23,"IC") -> 1 | W23: =IF(COUNTIF(B23:U23,"M")>0,"N/A absence longue",IF(V23>=2,"Atteint","Sous objectif")) -> Sous objectif
A24: Florian Roudier | V24: =COUNTIF(B24:U24,1)+COUNTIF(B24:U24,"IC") -> 0 | W24: =IF(COUNTIF(B24:U24,"M")>0,"N/A absence longue",IF(V24>=2,"Atteint","Sous objectif")) -> Sous objectif
A25: Nacim Souni | B25: 1 | C25: 1 | E25: 1 | G25: 1 | H25: 1 | J25: 1 | L25: 1 | O25: 1 | Q25: 1 | R25: 1 | T25: 1 | V25: =COUNTIF(B25:U25,1)+COUNTIF(B25:U25,"IC") -> 11 | W25: =IF(COUNTIF(B25:U25,"M")>0,"N/A absence longue",IF(V25>=2,"Atteint","Sous objectif")) -> Atteint
A26: Sandra Tang | O26: 1 | V26: =COUNTIF(B26:U26,1)+COUNTIF(B26:U26,"IC") -> 1 | W26: =IF(COUNTIF(B26:U26,"M")>0,"N/A absence longue",IF(V26>=2,"Atteint","Sous objectif")) -> Sous objectif
A27: Mathieu Ultsch | C27: 1 | H27: 1 | M27: 1 | O27: 1 | R27: 1 | V27: =COUNTIF(B27:U27,1)+COUNTIF(B27:U27,"IC") -> 5 | W27: =IF(COUNTIF(B27:U27,"M")>0,"N/A absence longue",IF(V27>=2,"Atteint","Sous objectif")) -> Atteint
A28: Amandine Ziegler | C28: 1 | H28: 1 | O28: 1 | R28: 1 | V28: =COUNTIF(B28:U28,1)+COUNTIF(B28:U28,"IC") -> 4 | W28: =IF(COUNTIF(B28:U28,"M")>0,"N/A absence longue",IF(V28>=2,"Atteint","Sous objectif")) -> Atteint
A30: — Événements —
A31: XO Day
A32: XO Product Day | O32: X
A33: Séminaire

Sheet Saisie 2026-03
A1: Saisie présence — Mars 2026
A3: Consultant | B3: 46083 | C3: 46084 | D3: 46085 | E3: 46086 | F3: 46087 | G3: 46090 | H3: 46091 | I3: 46092 | J3: 46093 | K3: 46094 | L3: 46097 | M3: 46098 | N3: 46099 | O3: 46100 | P3: 46101 | Q3: 46104 | R3: 46105 | S3: 46106 | T3: 46107 | U3: 46108 | V3: 46111 | W3: 46112 | X3: Total | Y3: Statut OKR
A4: Eva Andrzejewski | I4: 1 | M4: 1 | T4: 1 | X4: =COUNTIF(B4:W4,1)+COUNTIF(B4:W4,"IC") -> 3 | Y4: =IF(COUNTIF(B4:W4,"M")>0,"N/A absence longue",IF(X4>=2,"Atteint","Sous objectif")) -> Atteint
A5: Zelal Aslan | B5: M | C5: M | D5: M | E5: M | F5: M | G5: M | H5: M | I5: M | J5: M | K5: M | L5: M | M5: M | N5: M | O5: M | P5: M | Q5: M | R5: M | S5: M | T5: M | U5: M | V5: M | W5: M | X5: =COUNTIF(B5:W5,1)+COUNTIF(B5:W5,"IC") -> 0 | Y5: =IF(COUNTIF(B5:W5,"M")>0,"N/A absence longue",IF(X5>=2,"Atteint","Sous objectif")) -> N/A absence longue
A6: Calixte Bailly | X6: =COUNTIF(B6:W6,1)+COUNTIF(B6:W6,"IC") -> 0 | Y6: =IF(COUNTIF(B6:W6,"M")>0,"N/A absence longue",IF(X6>=2,"Atteint","Sous objectif")) -> Sous objectif
A7: Laureline Berthou | C7: 1 | M7: 1 | O7: 1 | R7: 1 | T7: 1 | W7: 1 | X7: =COUNTIF(B7:W7,1)+COUNTIF(B7:W7,"IC") -> 6 | Y7: =IF(COUNTIF(B7:W7,"M")>0,"N/A absence longue",IF(X7>=2,"Atteint","Sous objectif")) -> Atteint
A8: Julien Calvao | B8: IC | C8: IC | E8: IC | G8: IC | I8: IC | J8: IC | M8: IC | O8: IC | R8: IC | T8: IC | V8: IC | W8: IC | X8: =COUNTIF(B8:W8,1)+COUNTIF(B8:W8,"IC") -> 12 | Y8: =IF(COUNTIF(B8:W8,"M")>0,"N/A absence longue",IF(X8>=2,"Atteint","Sous objectif")) -> Atteint
A9: Axel Charletoux | I9: 1 | X9: =COUNTIF(B9:W9,1)+COUNTIF(B9:W9,"IC") -> 1 | Y9: =IF(COUNTIF(B9:W9,"M")>0,"N/A absence longue",IF(X9>=2,"Atteint","Sous objectif")) -> Sous objectif
A10: Matthieu Le Corre | C10: 1 | E10: 1 | J10: 1 | L10: 1 | O10: 1 | T10: 1 | W10: 1 | X10: =COUNTIF(B10:W10,1)+COUNTIF(B10:W10,"IC") -> 7 | Y10: =IF(COUNTIF(B10:W10,"M")>0,"N/A absence longue",IF(X10>=2,"Atteint","Sous objectif")) -> Atteint
A11: Geoffroy Debellabre | E11: 1 | O11: 1 | X11: =COUNTIF(B11:W11,1)+COUNTIF(B11:W11,"IC") -> 2 | Y11: =IF(COUNTIF(B11:W11,"M")>0,"N/A absence longue",IF(X11>=2,"Atteint","Sous objectif")) -> Atteint
A12: Anthéa Delpuech | T12: 1 | X12: =COUNTIF(B12:W12,1)+COUNTIF(B12:W12,"IC") -> 1 | Y12: =IF(COUNTIF(B12:W12,"M")>0,"N/A absence longue",IF(X12>=2,"Atteint","Sous objectif")) -> Sous objectif
A13: Alexandre Dieulesaint | I13: 1 | L13: 1 | X13: =COUNTIF(B13:W13,1)+COUNTIF(B13:W13,"IC") -> 2 | Y13: =IF(COUNTIF(B13:W13,"M")>0,"N/A absence longue",IF(X13>=2,"Atteint","Sous objectif")) -> Atteint
A14: Théo Esposito | I14: 1 | M14: 1 | X14: =COUNTIF(B14:W14,1)+COUNTIF(B14:W14,"IC") -> 2 | Y14: =IF(COUNTIF(B14:W14,"M")>0,"N/A absence longue",IF(X14>=2,"Atteint","Sous objectif")) -> Atteint
A15: Florian Le Fur | F15: 1 | I15: 1 | L15: 1 | O15: 1 | T15: 1 | X15: =COUNTIF(B15:W15,1)+COUNTIF(B15:W15,"IC") -> 5 | Y15: =IF(COUNTIF(B15:W15,"M")>0,"N/A absence longue",IF(X15>=2,"Atteint","Sous objectif")) -> Atteint
A16: Vincent Girard | H16: 1 | I16: 1 | L16: 1 | T16: 1 | X16: =COUNTIF(B16:W16,1)+COUNTIF(B16:W16,"IC") -> 4 | Y16: =IF(COUNTIF(B16:W16,"M")>0,"N/A absence longue",IF(X16>=2,"Atteint","Sous objectif")) -> Atteint
A17: Caroline Hamoud | T17: 1 | X17: =COUNTIF(B17:W17,1)+COUNTIF(B17:W17,"IC") -> 1 | Y17: =IF(COUNTIF(B17:W17,"M")>0,"N/A absence longue",IF(X17>=2,"Atteint","Sous objectif")) -> Sous objectif
A18: Félix Hantraye | T18: 1 | X18: =COUNTIF(B18:W18,1)+COUNTIF(B18:W18,"IC") -> 1 | Y18: =IF(COUNTIF(B18:W18,"M")>0,"N/A absence longue",IF(X18>=2,"Atteint","Sous objectif")) -> Sous objectif
A19: Simon Kerhyuel | T19: 1 | X19: =COUNTIF(B19:W19,1)+COUNTIF(B19:W19,"IC") -> 1 | Y19: =IF(COUNTIF(B19:W19,"M")>0,"N/A absence longue",IF(X19>=2,"Atteint","Sous objectif")) -> Sous objectif
A20: François L'Hostis | B20: 1 | G20: 1 | N20: 1 | T20: 1 | X20: =COUNTIF(B20:W20,1)+COUNTIF(B20:W20,"IC") -> 4 | Y20: =IF(COUNTIF(B20:W20,"M")>0,"N/A absence longue",IF(X20>=2,"Atteint","Sous objectif")) -> Atteint
A21: Barnabé Melaine | F21: 1 | M21: 1 | O21: 1 | T21: 1 | X21: =COUNTIF(B21:W21,1)+COUNTIF(B21:W21,"IC") -> 4 | Y21: =IF(COUNTIF(B21:W21,"M")>0,"N/A absence longue",IF(X21>=2,"Atteint","Sous objectif")) -> Atteint
A22: Bertrand Mignot | M22: 1 | X22: =COUNTIF(B22:W22,1)+COUNTIF(B22:W22,"IC") -> 1 | Y22: =IF(COUNTIF(B22:W22,"M")>0,"N/A absence longue",IF(X22>=2,"Atteint","Sous objectif")) -> Sous objectif
A23: Anthony Mocaer | T23: 1 | X23: =COUNTIF(B23:W23,1)+COUNTIF(B23:W23,"IC") -> 1 | Y23: =IF(COUNTIF(B23:W23,"M")>0,"N/A absence longue",IF(X23>=2,"Atteint","Sous objectif")) -> Sous objectif
A24: Esther Mussot | R24: 1 | T24: 1 | V24: 1 | W24: 1 | X24: =COUNTIF(B24:W24,1)+COUNTIF(B24:W24,"IC") -> 4 | Y24: =IF(COUNTIF(B24:W24,"M")>0,"N/A absence longue",IF(X24>=2,"Atteint","Sous objectif")) -> Atteint
A25: Florian Roudier | T25: 1 | X25: =COUNTIF(B25:W25,1)+COUNTIF(B25:W25,"IC") -> 1 | Y25: =IF(COUNTIF(B25:W25,"M")>0,"N/A absence longue",IF(X25>=2,"Atteint","Sous objectif")) -> Sous objectif
A26: Nacim Souni | X26: =COUNTIF(B26:W26,1)+COUNTIF(B26:W26,"IC") -> 0 | Y26: =IF(COUNTIF(B26:W26,"M")>0,"N/A absence longue",IF(X26>=2,"Atteint","Sous objectif")) -> Sous objectif
A27: Sandra Tang | O27: 1 | T27: 1 | X27: =COUNTIF(B27:W27,1)+COUNTIF(B27:W27,"IC") -> 2 | Y27: =IF(COUNTIF(B27:W27,"M")>0,"N/A absence longue",IF(X27>=2,"Atteint","Sous objectif")) -> Atteint
A28: Mathieu Ultsch | I28: 1 | M28: 1 | R28: 1 | W28: 1 | X28: =COUNTIF(B28:W28,1)+COUNTIF(B28:W28,"IC") -> 4 | Y28: =IF(COUNTIF(B28:W28,"M")>0,"N/A absence longue",IF(X28>=2,"Atteint","Sous objectif")) -> Atteint
A29: Amandine Ziegler | M29: 1 | R29: 1 | T29: 1 | X29: =COUNTIF(B29:W29,1)+COUNTIF(B29:W29,"IC") -> 3 | Y29: =IF(COUNTIF(B29:W29,"M")>0,"N/A absence longue",IF(X29>=2,"Atteint","Sous objectif")) -> Atteint
A31: — Événements —
A32: XO Day | T32: X
A33: XO Product Day
A34: Séminaire

Sheet Saisie 2026-04
A1: Saisie présence — Avril 2026
A3: Consultant | B3: 46113 | C3: 46114 | D3: 46115 | E3: 46118 | F3: 46119 | G3: 46120 | H3: 46121 | I3: 46122 | J3: 46125 | K3: 46126 | L3: 46127 | M3: 46128 | N3: 46129 | O3: 46132 | P3: 46133 | Q3: 46134 | R3: 46135 | S3: 46136 | T3: 46139 | U3: 46140 | V3: 46141 | W3: 46142 | X3: Total | Y3: Statut OKR
A4: Eva Andrzejewski | R4: 1 | U4: 1 | X4: =COUNTIF(B4:W4,1)+COUNTIF(B4:W4,"IC") -> 2 | Y4: =IF(COUNTIF(B4:W4,"M")>0,"N/A absence longue",IF(X4>=2,"Atteint","Sous objectif")) -> Atteint
A5: Zelal Aslan | C5: IC | F5: IC | H5: IC | J5: IC | K5: IC | M5: IC | O5: IC | R5: IC | T5: IC | U5: IC | W5: IC | X5: =COUNTIF(B5:W5,1)+COUNTIF(B5:W5,"IC") -> 11 | Y5: =IF(COUNTIF(B5:W5,"M")>0,"N/A absence longue",IF(X5>=2,"Atteint","Sous objectif")) -> Atteint
A6: Calixte Bailly | R6: 1 | X6: =COUNTIF(B6:W6,1)+COUNTIF(B6:W6,"IC") -> 1 | Y6: =IF(COUNTIF(B6:W6,"M")>0,"N/A absence longue",IF(X6>=2,"Atteint","Sous objectif")) -> Sous objectif
A7: Laureline Berthou | K7: 1 | M7: 1 | R7: 1 | U7: 1 | X7: =COUNTIF(B7:W7,1)+COUNTIF(B7:W7,"IC") -> 4 | Y7: =IF(COUNTIF(B7:W7,"M")>0,"N/A absence longue",IF(X7>=2,"Atteint","Sous objectif")) -> Atteint
A8: Julien Calvao | C8: IC | F8: IC | H8: IC | J8: IC | K8: IC | M8: IC | O8: IC | P8: IC | R8: IC | T8: IC | U8: IC | W8: IC | X8: =COUNTIF(B8:W8,1)+COUNTIF(B8:W8,"IC") -> 12 | Y8: =IF(COUNTIF(B8:W8,"M")>0,"N/A absence longue",IF(X8>=2,"Atteint","Sous objectif")) -> Atteint
A9: Axel Charletoux | F9: 1 | R9: 1 | X9: =COUNTIF(B9:W9,1)+COUNTIF(B9:W9,"IC") -> 2 | Y9: =IF(COUNTIF(B9:W9,"M")>0,"N/A absence longue",IF(X9>=2,"Atteint","Sous objectif")) -> Atteint
A10: Matthieu Le Corre | H10: 1 | K10: 1 | M10: 1 | R10: 1 | U10: 1 | W10: 1 | X10: =COUNTIF(B10:W10,1)+COUNTIF(B10:W10,"IC") -> 6 | Y10: =IF(COUNTIF(B10:W10,"M")>0,"N/A absence longue",IF(X10>=2,"Atteint","Sous objectif")) -> Atteint
A11: Geoffroy Debellabre | C11: 1 | R11: 1 | X11: =COUNTIF(B11:W11,1)+COUNTIF(B11:W11,"IC") -> 2 | Y11: =IF(COUNTIF(B11:W11,"M")>0,"N/A absence longue",IF(X11>=2,"Atteint","Sous objectif")) -> Atteint
A12: Anthéa Delpuech | R12: 1 | X12: =COUNTIF(B12:W12,1)+COUNTIF(B12:W12,"IC") -> 1 | Y12: =IF(COUNTIF(B12:W12,"M")>0,"N/A absence longue",IF(X12>=2,"Atteint","Sous objectif")) -> Sous objectif
A13: Alexandre Dieulesaint | F13: 1 | X13: =COUNTIF(B13:W13,1)+COUNTIF(B13:W13,"IC") -> 1 | Y13: =IF(COUNTIF(B13:W13,"M")>0,"N/A absence longue",IF(X13>=2,"Atteint","Sous objectif")) -> Sous objectif
A14: Théo Esposito | M14: 1 | R14: 1 | X14: =COUNTIF(B14:W14,1)+COUNTIF(B14:W14,"IC") -> 2 | Y14: =IF(COUNTIF(B14:W14,"M")>0,"N/A absence longue",IF(X14>=2,"Atteint","Sous objectif")) -> Atteint
A15: Florian Le Fur | J15: 1 | L15: 1 | R15: 1 | U15: 1 | X15: =COUNTIF(B15:W15,1)+COUNTIF(B15:W15,"IC") -> 4 | Y15: =IF(COUNTIF(B15:W15,"M")>0,"N/A absence longue",IF(X15>=2,"Atteint","Sous objectif")) -> Atteint
A16: Vincent Girard | F16: 1 | R16: 1 | X16: =COUNTIF(B16:W16,1)+COUNTIF(B16:W16,"IC") -> 2 | Y16: =IF(COUNTIF(B16:W16,"M")>0,"N/A absence longue",IF(X16>=2,"Atteint","Sous objectif")) -> Atteint
A17: Caroline Hamoud | F17: 1 | O17: IC | Q17: IC | X17: =COUNTIF(B17:W17,1)+COUNTIF(B17:W17,"IC") -> 3 | Y17: =IF(COUNTIF(B17:W17,"M")>0,"N/A absence longue",IF(X17>=2,"Atteint","Sous objectif")) -> Atteint
A18: Félix Hantraye | F18: 1 | R18: 1 | X18: =COUNTIF(B18:W18,1)+COUNTIF(B18:W18,"IC") -> 2 | Y18: =IF(COUNTIF(B18:W18,"M")>0,"N/A absence longue",IF(X18>=2,"Atteint","Sous objectif")) -> Atteint
A19: Simon Kerhyuel | F19: 1 | R19: 1 | U19: 1 | X19: =COUNTIF(B19:W19,1)+COUNTIF(B19:W19,"IC") -> 3 | Y19: =IF(COUNTIF(B19:W19,"M")>0,"N/A absence longue",IF(X19>=2,"Atteint","Sous objectif")) -> Atteint
A20: François L'Hostis | H20: 1 | L20: 1 | R20: 1 | X20: =COUNTIF(B20:W20,1)+COUNTIF(B20:W20,"IC") -> 3 | Y20: =IF(COUNTIF(B20:W20,"M")>0,"N/A absence longue",IF(X20>=2,"Atteint","Sous objectif")) -> Atteint
A21: Barnabé Melaine | F21: 1 | J21: 1 | R21: 1 | X21: =COUNTIF(B21:W21,1)+COUNTIF(B21:W21,"IC") -> 3 | Y21: =IF(COUNTIF(B21:W21,"M")>0,"N/A absence longue",IF(X21>=2,"Atteint","Sous objectif")) -> Atteint
A22: Bertrand Mignot | M22: 1 | R22: 1 | X22: =COUNTIF(B22:W22,1)+COUNTIF(B22:W22,"IC") -> 2 | Y22: =IF(COUNTIF(B22:W22,"M")>0,"N/A absence longue",IF(X22>=2,"Atteint","Sous objectif")) -> Atteint
A23: Anthony Mocaer | M23: 1 | R23: 1 | X23: =COUNTIF(B23:W23,1)+COUNTIF(B23:W23,"IC") -> 2 | Y23: =IF(COUNTIF(B23:W23,"M")>0,"N/A absence longue",IF(X23>=2,"Atteint","Sous objectif")) -> Atteint
A24: Esther Mussot | C24: IC | R24: 1 | X24: =COUNTIF(B24:W24,1)+COUNTIF(B24:W24,"IC") -> 2 | Y24: =IF(COUNTIF(B24:W24,"M")>0,"N/A absence longue",IF(X24>=2,"Atteint","Sous objectif")) -> Atteint
A25: Florian Roudier | J25: 1 | R25: 1 | X25: =COUNTIF(B25:W25,1)+COUNTIF(B25:W25,"IC") -> 2 | Y25: =IF(COUNTIF(B25:W25,"M")>0,"N/A absence longue",IF(X25>=2,"Atteint","Sous objectif")) -> Atteint
A26: Nacim Souni | R26: 1 | X26: =COUNTIF(B26:W26,1)+COUNTIF(B26:W26,"IC") -> 1 | Y26: =IF(COUNTIF(B26:W26,"M")>0,"N/A absence longue",IF(X26>=2,"Atteint","Sous objectif")) -> Sous objectif
A27: Sandra Tang | R27: 1 | U27: 1 | X27: =COUNTIF(B27:W27,1)+COUNTIF(B27:W27,"IC") -> 2 | Y27: =IF(COUNTIF(B27:W27,"M")>0,"N/A absence longue",IF(X27>=2,"Atteint","Sous objectif")) -> Atteint
A28: Mathieu Ultsch | F28: 1 | K28: 1 | R28: 1 | X28: =COUNTIF(B28:W28,1)+COUNTIF(B28:W28,"IC") -> 3 | Y28: =IF(COUNTIF(B28:W28,"M")>0,"N/A absence longue",IF(X28>=2,"Atteint","Sous objectif")) -> Atteint
A29: Amandine Ziegler | F29: 1 | K29: 1 | P29: 1 | R29: 1 | X29: =COUNTIF(B29:W29,1)+COUNTIF(B29:W29,"IC") -> 4 | Y29: =IF(COUNTIF(B29:W29,"M")>0,"N/A absence longue",IF(X29>=2,"Atteint","Sous objectif")) -> Atteint
A31: — Événements —
A32: XO Day | R32: X
A33: XO Product Day
A34: Séminaire

Sheet Saisie 2026-05
A1: Saisie présence — Mai 2026
A3: Consultant | B3: 46146 | C3: 46147 | D3: 46148 | E3: 46149 | F3: 46150 | G3: 46153 | H3: 46154 | I3: 46155 | J3: 46157 | K3: 46160 | L3: 46161 | M3: 46162 | N3: 46163 | O3: 46164 | P3: 46168 | Q3: 46169 | R3: 46170 | S3: 46171 | T3: Total | U3: Statut OKR
A4: Eva Andrzejewski | D4: 1 | L4: 1 | R4: 1 | T4: =COUNTIF(B4:S4,1)+COUNTIF(B4:S4,"IC") -> 3 | U4: =IF(COUNTIF(B4:S4,"M")>0,"N/A absence longue",IF(T4>=2,"Atteint","Sous objectif")) -> Atteint
A5: Zelal Aslan | B5: IC | C5: IC | E5: IC | H5: IC | K5: IC | L5: IC | N5: IC | R5: IC | T5: =COUNTIF(B5:S5,1)+COUNTIF(B5:S5,"IC") -> 8 | U5: =IF(COUNTIF(B5:S5,"M")>0,"N/A absence longue",IF(T5>=2,"Atteint","Sous objectif")) -> Atteint
A6: Calixte Bailly | R6: 1 | T6: =COUNTIF(B6:S6,1)+COUNTIF(B6:S6,"IC") -> 1 | U6: =IF(COUNTIF(B6:S6,"M")>0,"N/A absence longue",IF(T6>=2,"Atteint","Sous objectif")) -> Sous objectif
A7: Laureline Berthou | L7: 1 | N7: 1 | P7: 1 | Q7: 1 | R7: 1 | T7: =COUNTIF(B7:S7,1)+COUNTIF(B7:S7,"IC") -> 5 | U7: =IF(COUNTIF(B7:S7,"M")>0,"N/A absence longue",IF(T7>=2,"Atteint","Sous objectif")) -> Atteint
A8: Julien Calvao | B8: IC | C8: IC | D8: IC | E8: IC | G8: IC | H8: IC | J8: IC | K8: IC | L8: IC | N8: IC | R8: 1 | T8: =COUNTIF(B8:S8,1)+COUNTIF(B8:S8,"IC") -> 11 | U8: =IF(COUNTIF(B8:S8,"M")>0,"N/A absence longue",IF(T8>=2,"Atteint","Sous objectif")) -> Atteint
A9: Axel Charletoux | B9: IC | D9: IC | E9: IC | G9: IC | H9: IC | J9: IC | K9: IC | L9: IC | N9: IC | R9: 1 | T9: =COUNTIF(B9:S9,1)+COUNTIF(B9:S9,"IC") -> 10 | U9: =IF(COUNTIF(B9:S9,"M")>0,"N/A absence longue",IF(T9>=2,"Atteint","Sous objectif")) -> Atteint
A10: Matthieu Le Corre | C10: 1 | E10: 1 | H10: 1 | L10: 1 | N10: 1 | R10: 1 | T10: =COUNTIF(B10:S10,1)+COUNTIF(B10:S10,"IC") -> 6 | U10: =IF(COUNTIF(B10:S10,"M")>0,"N/A absence longue",IF(T10>=2,"Atteint","Sous objectif")) -> Atteint
A11: Geoffroy Debellabre | N11: 1 | T11: =COUNTIF(B11:S11,1)+COUNTIF(B11:S11,"IC") -> 1 | U11: =IF(COUNTIF(B11:S11,"M")>0,"N/A absence longue",IF(T11>=2,"Atteint","Sous objectif")) -> Sous objectif
A12: Anthéa Delpuech | R12: 1 | T12: =COUNTIF(B12:S12,1)+COUNTIF(B12:S12,"IC") -> 1 | U12: =IF(COUNTIF(B12:S12,"M")>0,"N/A absence longue",IF(T12>=2,"Atteint","Sous objectif")) -> Sous objectif
A13: Alexandre Dieulesaint | L13: 1 | T13: =COUNTIF(B13:S13,1)+COUNTIF(B13:S13,"IC") -> 1 | U13: =IF(COUNTIF(B13:S13,"M")>0,"N/A absence longue",IF(T13>=2,"Atteint","Sous objectif")) -> Sous objectif
A14: Théo Esposito | R14: 1 | T14: =COUNTIF(B14:S14,1)+COUNTIF(B14:S14,"IC") -> 1 | U14: =IF(COUNTIF(B14:S14,"M")>0,"N/A absence longue",IF(T14>=2,"Atteint","Sous objectif")) -> Sous objectif
A15: Florian Le Fur | I15: 1 | N15: 1 | R15: 1 | T15: =COUNTIF(B15:S15,1)+COUNTIF(B15:S15,"IC") -> 3 | U15: =IF(COUNTIF(B15:S15,"M")>0,"N/A absence longue",IF(T15>=2,"Atteint","Sous objectif")) -> Atteint
A16: Vincent Girard | D16: 1 | L16: 1 | R16: 1 | T16: =COUNTIF(B16:S16,1)+COUNTIF(B16:S16,"IC") -> 3 | U16: =IF(COUNTIF(B16:S16,"M")>0,"N/A absence longue",IF(T16>=2,"Atteint","Sous objectif")) -> Atteint
A17: Caroline Hamoud | B17: IC | D17: IC | E17: IC | G17: IC | H17: IC | Q17: IC | R17: IC | S17: IC | T17: =COUNTIF(B17:S17,1)+COUNTIF(B17:S17,"IC") -> 8 | U17: =IF(COUNTIF(B17:S17,"M")>0,"N/A absence longue",IF(T17>=2,"Atteint","Sous objectif")) -> Atteint
A18: Félix Hantraye | R18: 1 | T18: =COUNTIF(B18:S18,1)+COUNTIF(B18:S18,"IC") -> 1 | U18: =IF(COUNTIF(B18:S18,"M")>0,"N/A absence longue",IF(T18>=2,"Atteint","Sous objectif")) -> Sous objectif
A19: Simon Kerhyuel | L19: 1 | R19: 1 | T19: =COUNTIF(B19:S19,1)+COUNTIF(B19:S19,"IC") -> 2 | U19: =IF(COUNTIF(B19:S19,"M")>0,"N/A absence longue",IF(T19>=2,"Atteint","Sous objectif")) -> Atteint
A20: François L'Hostis | R20: 1 | T20: =COUNTIF(B20:S20,1)+COUNTIF(B20:S20,"IC") -> 1 | U20: =IF(COUNTIF(B20:S20,"M")>0,"N/A absence longue",IF(T20>=2,"Atteint","Sous objectif")) -> Sous objectif
A21: Barnabé Melaine | E21: 1 | L21: 1 | M21: 1 | O21: 1 | R21: 1 | T21: =COUNTIF(B21:S21,1)+COUNTIF(B21:S21,"IC") -> 5 | U21: =IF(COUNTIF(B21:S21,"M")>0,"N/A absence longue",IF(T21>=2,"Atteint","Sous objectif")) -> Atteint
A22: Bertrand Mignot | T22: =COUNTIF(B22:S22,1)+COUNTIF(B22:S22,"IC") -> 0 | U22: =IF(COUNTIF(B22:S22,"M")>0,"N/A absence longue",IF(T22>=2,"Atteint","Sous objectif")) -> Sous objectif
A23: Anthony Mocaer | D23: 1 | R23: 1 | T23: =COUNTIF(B23:S23,1)+COUNTIF(B23:S23,"IC") -> 2 | U23: =IF(COUNTIF(B23:S23,"M")>0,"N/A absence longue",IF(T23>=2,"Atteint","Sous objectif")) -> Atteint
A24: Esther Mussot | R24: 1 | T24: =COUNTIF(B24:S24,1)+COUNTIF(B24:S24,"IC") -> 1 | U24: =IF(COUNTIF(B24:S24,"M")>0,"N/A absence longue",IF(T24>=2,"Atteint","Sous objectif")) -> Sous objectif
A25: Florian Roudier | D25: 1 | M25: 1 | R25: 1 | T25: =COUNTIF(B25:S25,1)+COUNTIF(B25:S25,"IC") -> 3 | U25: =IF(COUNTIF(B25:S25,"M")>0,"N/A absence longue",IF(T25>=2,"Atteint","Sous objectif")) -> Atteint
A26: Nacim Souni | T26: =COUNTIF(B26:S26,1)+COUNTIF(B26:S26,"IC") -> 0 | U26: =IF(COUNTIF(B26:S26,"M")>0,"N/A absence longue",IF(T26>=2,"Atteint","Sous objectif")) -> Sous objectif
A27: Sandra Tang | D27: 1 | R27: 1 | T27: =COUNTIF(B27:S27,1)+COUNTIF(B27:S27,"IC") -> 2 | U27: =IF(COUNTIF(B27:S27,"M")>0,"N/A absence longue",IF(T27>=2,"Atteint","Sous objectif")) -> Atteint
A28: Mathieu Ultsch | L28: 1 | T28: =COUNTIF(B28:S28,1)+COUNTIF(B28:S28,"IC") -> 1 | U28: =IF(COUNTIF(B28:S28,"M")>0,"N/A absence longue",IF(T28>=2,"Atteint","Sous objectif")) -> Sous objectif
A29: Amandine Ziegler | R29: 1 | T29: =COUNTIF(B29:S29,1)+COUNTIF(B29:S29,"IC") -> 1 | U29: =IF(COUNTIF(B29:S29,"M")>0,"N/A absence longue",IF(T29>=2,"Atteint","Sous objectif")) -> Sous objectif
A31: — Événements —
A32: XO Day | R32: X
A33: XO Product Day | D33: X
A34: Séminaire

Sheet Saisie 2026-06
A1: Saisie présence — Juin 2026
A3: Consultant | B3: 46174 | C3: 46175 | D3: 46176 | E3: 46177 | F3: 46178 | G3: 46181 | H3: 46182 | I3: 46183 | J3: 46184 | K3: 46185 | L3: 46188 | M3: 46189 | N3: 46190 | O3: 46191 | P3: 46192 | Q3: 46195 | R3: 46196 | S3: 46197 | T3: 46198 | U3: 46199 | V3: 46202 | W3: 46203 | X3: Total | Y3: Statut OKR
A4: Eva Andrzejewski | H4: 1 | P4: 1 | X4: =COUNTIF(B4:W4,1)+COUNTIF(B4:W4,"IC") -> 2 | Y4: =IF(COUNTIF(B4:W4,"M")>0,"N/A absence longue",IF(X4>=2,"Atteint","Sous objectif")) -> Atteint
A5: Zelal Aslan | B5: IC | C5: IC | E5: IC | G5: IC | H5: IC | J5: IC | L5: IC | O5: IC | P5: IC | X5: =COUNTIF(B5:W5,1)+COUNTIF(B5:W5,"IC") -> 9 | Y5: =IF(COUNTIF(B5:W5,"M")>0,"N/A absence longue",IF(X5>=2,"Atteint","Sous objectif")) -> Atteint
A6: Calixte Bailly | Q6: 1 | X6: =COUNTIF(B6:W6,1)+COUNTIF(B6:W6,"IC") -> 1 | Y6: =IF(COUNTIF(B6:W6,"M")>0,"N/A absence longue",IF(X6>=2,"Atteint","Sous objectif")) -> Sous objectif
A7: Laureline Berthou | D7: 1 | H7: 1 | J7: 1 | M7: 1 | O7: 1 | P7: 1 | R7: 1 | X7: =COUNTIF(B7:W7,1)+COUNTIF(B7:W7,"IC") -> 7 | Y7: =IF(COUNTIF(B7:W7,"M")>0,"N/A absence longue",IF(X7>=2,"Atteint","Sous objectif")) -> Atteint
A8: Agnes Bregeon | B8: IC | C8: IC | D8: IC | E8: IC | G8: IC | H8: IC | J8: IC | L8: IC | M8: IC | N8: IC | O8: IC | P8: IC | Q8: IC | R8: IC | T8: IC | V8: IC | W8: IC | X8: =COUNTIF(B8:W8,1)+COUNTIF(B8:W8,"IC") -> 17 | Y8: =IF(COUNTIF(B8:W8,"M")>0,"N/A absence longue",IF(X8>=2,"Atteint","Sous objectif")) -> Atteint
A9: Julien Calvao | E9: 1 | T9: 1 | X9: =COUNTIF(B9:W9,1)+COUNTIF(B9:W9,"IC") -> 2 | Y9: =IF(COUNTIF(B9:W9,"M")>0,"N/A absence longue",IF(X9>=2,"Atteint","Sous objectif")) -> Atteint
A10: Axel Charletoux | B10: 1 | P10: 1 | S10: 1 | X10: =COUNTIF(B10:W10,1)+COUNTIF(B10:W10,"IC") -> 3 | Y10: =IF(COUNTIF(B10:W10,"M")>0,"N/A absence longue",IF(X10>=2,"Atteint","Sous objectif")) -> Atteint
A11: Matthieu Le Corre | E11: 1 | H11: 1 | J11: 1 | M11: 1 | P11: 1 | R11: 1 | T11: 1 | W11: 1 | X11: =COUNTIF(B11:W11,1)+COUNTIF(B11:W11,"IC") -> 8 | Y11: =IF(COUNTIF(B11:W11,"M")>0,"N/A absence longue",IF(X11>=2,"Atteint","Sous objectif")) -> Atteint
A12: Geoffroy Debellabre | P12: 1 | W12: 1 | X12: =COUNTIF(B12:W12,1)+COUNTIF(B12:W12,"IC") -> 2 | Y12: =IF(COUNTIF(B12:W12,"M")>0,"N/A absence longue",IF(X12>=2,"Atteint","Sous objectif")) -> Atteint
A13: Anthéa Delpuech | E13: 1 | P13: 1 | X13: =COUNTIF(B13:W13,1)+COUNTIF(B13:W13,"IC") -> 2 | Y13: =IF(COUNTIF(B13:W13,"M")>0,"N/A absence longue",IF(X13>=2,"Atteint","Sous objectif")) -> Atteint
A14: Alexandre Dieulesaint | G14: 1 | P14: 1 | X14: =COUNTIF(B14:W14,1)+COUNTIF(B14:W14,"IC") -> 2 | Y14: =IF(COUNTIF(B14:W14,"M")>0,"N/A absence longue",IF(X14>=2,"Atteint","Sous objectif")) -> Atteint
A15: Théo Esposito | D15: 1 | H15: 1 | W15: 1 | X15: =COUNTIF(B15:W15,1)+COUNTIF(B15:W15,"IC") -> 3 | Y15: =IF(COUNTIF(B15:W15,"M")>0,"N/A absence longue",IF(X15>=2,"Atteint","Sous objectif")) -> Atteint
A16: Florian Le Fur | C16: 1 | H16: 1 | P16: 1 | R16: 1 | T16: 1 | W16: 1 | X16: =COUNTIF(B16:W16,1)+COUNTIF(B16:W16,"IC") -> 6 | Y16: =IF(COUNTIF(B16:W16,"M")>0,"N/A absence longue",IF(X16>=2,"Atteint","Sous objectif")) -> Atteint
A17: Vincent Girard | R17: 1 | W17: 1 | X17: =COUNTIF(B17:W17,1)+COUNTIF(B17:W17,"IC") -> 2 | Y17: =IF(COUNTIF(B17:W17,"M")>0,"N/A absence longue",IF(X17>=2,"Atteint","Sous objectif")) -> Atteint
A18: Caroline Hamoud | C18: IC | E18: IC | G18: IC | H18: IC | J18: IC | L18: IC | O18: IC | P18: IC | Q18: IC | R18: IC | T18: IC | V18: IC | W18: IC | X18: =COUNTIF(B18:W18,1)+COUNTIF(B18:W18,"IC") -> 13 | Y18: =IF(COUNTIF(B18:W18,"M")>0,"N/A absence longue",IF(X18>=2,"Atteint","Sous objectif")) -> Atteint
A19: Félix Hantraye | P19: 1 | R19: 1 | W19: 1 | X19: =COUNTIF(B19:W19,1)+COUNTIF(B19:W19,"IC") -> 3 | Y19: =IF(COUNTIF(B19:W19,"M")>0,"N/A absence longue",IF(X19>=2,"Atteint","Sous objectif")) -> Atteint
A20: Simon Kerhyuel | P20: 1 | X20: =COUNTIF(B20:W20,1)+COUNTIF(B20:W20,"IC") -> 1 | Y20: =IF(COUNTIF(B20:W20,"M")>0,"N/A absence longue",IF(X20>=2,"Atteint","Sous objectif")) -> Sous objectif
A21: François L'Hostis | B21: 1 | G21: 1 | N21: 1 | P21: 1 | X21: =COUNTIF(B21:W21,1)+COUNTIF(B21:W21,"IC") -> 4 | Y21: =IF(COUNTIF(B21:W21,"M")>0,"N/A absence longue",IF(X21>=2,"Atteint","Sous objectif")) -> Atteint
A22: Barnabé Melaine | E22: 1 | F22: 1 | H22: 1 | M22: 1 | O22: mu | P22: 1 | Q22: 1 | R22: 1 | T22: 1 | U22: 1 | W22: 1 | X22: =COUNTIF(B22:W22,1)+COUNTIF(B22:W22,"IC") -> 10 | Y22: =IF(COUNTIF(B22:W22,"M")>0,"N/A absence longue",IF(X22>=2,"Atteint","Sous objectif")) -> Atteint
A23: Bertrand Mignot | E23: 1 | X23: =COUNTIF(B23:W23,1)+COUNTIF(B23:W23,"IC") -> 1 | Y23: =IF(COUNTIF(B23:W23,"M")>0,"N/A absence longue",IF(X23>=2,"Atteint","Sous objectif")) -> Sous objectif
A24: Anthony Mocaer | P24: 1 | V24: 1 | X24: =COUNTIF(B24:W24,1)+COUNTIF(B24:W24,"IC") -> 2 | Y24: =IF(COUNTIF(B24:W24,"M")>0,"N/A absence longue",IF(X24>=2,"Atteint","Sous objectif")) -> Atteint
A25: Esther Mussot | X25: =COUNTIF(B25:W25,1)+COUNTIF(B25:W25,"IC") -> 0 | Y25: =IF(COUNTIF(B25:W25,"M")>0,"N/A absence longue",IF(X25>=2,"Atteint","Sous objectif")) -> Sous objectif
A26: Florian Roudier | P26: 1 | X26: =COUNTIF(B26:W26,1)+COUNTIF(B26:W26,"IC") -> 1 | Y26: =IF(COUNTIF(B26:W26,"M")>0,"N/A absence longue",IF(X26>=2,"Atteint","Sous objectif")) -> Sous objectif
A27: Nacim Souni | X27: =COUNTIF(B27:W27,1)+COUNTIF(B27:W27,"IC") -> 0 | Y27: =IF(COUNTIF(B27:W27,"M")>0,"N/A absence longue",IF(X27>=2,"Atteint","Sous objectif")) -> Sous objectif
A28: Sandra Tang | H28: 1 | W28: 1 | X28: =COUNTIF(B28:W28,1)+COUNTIF(B28:W28,"IC") -> 2 | Y28: =IF(COUNTIF(B28:W28,"M")>0,"N/A absence longue",IF(X28>=2,"Atteint","Sous objectif")) -> Atteint
A29: Mathieu Ultsch | H29: 1 | P29: 1 | W29: 1 | X29: =COUNTIF(B29:W29,1)+COUNTIF(B29:W29,"IC") -> 3 | Y29: =IF(COUNTIF(B29:W29,"M")>0,"N/A absence longue",IF(X29>=2,"Atteint","Sous objectif")) -> Atteint
A30: Amandine Ziegler | H30: 1 | M30: 1 | P30: 1 | Q30: 1 | R30: 1 | X30: =COUNTIF(B30:W30,1)+COUNTIF(B30:W30,"IC") -> 5 | Y30: =IF(COUNTIF(B30:W30,"M")>0,"N/A absence longue",IF(X30>=2,"Atteint","Sous objectif")) -> Atteint
A32: — Événements —
A33: XO Day | P33: X
A34: XO Product Day | H34: X
A35: Séminaire

Sheet Saisie 2026-07
A1: Saisie présence — Juillet 2026
A3: Consultant | B3: 46204 | C3: 46205 | D3: 46206 | E3: 46209 | F3: 46210 | G3: 46211 | H3: 46212 | I3: 46213 | J3: 46216 | K3: 46218 | L3: 46219 | M3: 46220 | N3: 46223 | O3: 46224 | P3: 46225 | Q3: 46226 | R3: 46227 | S3: 46230 | T3: 46231 | U3: 46232 | V3: 46233 | W3: 46234 | X3: Total | Y3: Statut OKR
A4: Eva Andrzejewski | F4: 1 | O4: 1 | X4: =COUNTIF(B4:W4,1)+COUNTIF(B4:W4,"IC") -> 2 | Y4: =IF(COUNTIF(B4:W4,"M")>0,"N/A absence longue",IF(X4>=2,"Atteint","Sous objectif")) -> Atteint
A5: Zelal Aslan | J5: IC | X5: =COUNTIF(B5:W5,1)+COUNTIF(B5:W5,"IC") -> 1 | Y5: =IF(COUNTIF(B5:W5,"M")>0,"N/A absence longue",IF(X5>=2,"Atteint","Sous objectif")) -> Sous objectif
A6: Calixte Bailly | X6: =COUNTIF(B6:W6,1)+COUNTIF(B6:W6,"IC") -> 0 | Y6: =IF(COUNTIF(B6:W6,"M")>0,"N/A absence longue",IF(X6>=2,"Atteint","Sous objectif")) -> Sous objectif
A7: Laureline Berthou | C7: 1 | F7: 1 | L7: 1 | X7: =COUNTIF(B7:W7,1)+COUNTIF(B7:W7,"IC") -> 3 | Y7: =IF(COUNTIF(B7:W7,"M")>0,"N/A absence longue",IF(X7>=2,"Atteint","Sous objectif")) -> Atteint
A8: Agnes Bregeon | C8: IC | E8: IC | F8: IC | H8: IC | J8: IC | X8: =COUNTIF(B8:W8,1)+COUNTIF(B8:W8,"IC") -> 5 | Y8: =IF(COUNTIF(B8:W8,"M")>0,"N/A absence longue",IF(X8>=2,"Atteint","Sous objectif")) -> Atteint
A9: Julien Calvao | X9: =COUNTIF(B9:W9,1)+COUNTIF(B9:W9,"IC") -> 0 | Y9: =IF(COUNTIF(B9:W9,"M")>0,"N/A absence longue",IF(X9>=2,"Atteint","Sous objectif")) -> Sous objectif
A10: Axel Charletoux | B10: 1 | T10: 1 | X10: =COUNTIF(B10:W10,1)+COUNTIF(B10:W10,"IC") -> 2 | Y10: =IF(COUNTIF(B10:W10,"M")>0,"N/A absence longue",IF(X10>=2,"Atteint","Sous objectif")) -> Atteint
A11: Matthieu Le Corre | F11: 1 | H11: 1 | L11: 1 | T11: 1 | X11: =COUNTIF(B11:W11,1)+COUNTIF(B11:W11,"IC") -> 4 | Y11: =IF(COUNTIF(B11:W11,"M")>0,"N/A absence longue",IF(X11>=2,"Atteint","Sous objectif")) -> Atteint
A12: Geoffroy Debellabre | X12: =COUNTIF(B12:W12,1)+COUNTIF(B12:W12,"IC") -> 0 | Y12: =IF(COUNTIF(B12:W12,"M")>0,"N/A absence longue",IF(X12>=2,"Atteint","Sous objectif")) -> Sous objectif
A13: Anthéa Delpuech | O13: 1 | X13: =COUNTIF(B13:W13,1)+COUNTIF(B13:W13,"IC") -> 1 | Y13: =IF(COUNTIF(B13:W13,"M")>0,"N/A absence longue",IF(X13>=2,"Atteint","Sous objectif")) -> Sous objectif
A14: Alexandre Dieulesaint | F14: 1 | X14: =COUNTIF(B14:W14,1)+COUNTIF(B14:W14,"IC") -> 1 | Y14: =IF(COUNTIF(B14:W14,"M")>0,"N/A absence longue",IF(X14>=2,"Atteint","Sous objectif")) -> Sous objectif
A15: Théo Esposito | F15: 1 | X15: =COUNTIF(B15:W15,1)+COUNTIF(B15:W15,"IC") -> 1 | Y15: =IF(COUNTIF(B15:W15,"M")>0,"N/A absence longue",IF(X15>=2,"Atteint","Sous objectif")) -> Sous objectif
A16: Florian Le Fur | P16: 1 | Q16: 1 | X16: =COUNTIF(B16:W16,1)+COUNTIF(B16:W16,"IC") -> 2 | Y16: =IF(COUNTIF(B16:W16,"M")>0,"N/A absence longue",IF(X16>=2,"Atteint","Sous objectif")) -> Atteint
A17: Vincent Girard | F17: 1 | X17: =COUNTIF(B17:W17,1)+COUNTIF(B17:W17,"IC") -> 1 | Y17: =IF(COUNTIF(B17:W17,"M")>0,"N/A absence longue",IF(X17>=2,"Atteint","Sous objectif")) -> Sous objectif
A18: Caroline Hamoud | C18: IC | F18: IC | H18: IC | L18: IC | O18: IC | X18: =COUNTIF(B18:W18,1)+COUNTIF(B18:W18,"IC") -> 5 | Y18: =IF(COUNTIF(B18:W18,"M")>0,"N/A absence longue",IF(X18>=2,"Atteint","Sous objectif")) -> Atteint
A19: Félix Hantraye | F19: 1 | O19: 1 | X19: =COUNTIF(B19:W19,1)+COUNTIF(B19:W19,"IC") -> 2 | Y19: =IF(COUNTIF(B19:W19,"M")>0,"N/A absence longue",IF(X19>=2,"Atteint","Sous objectif")) -> Atteint
A20: Simon Kerhyuel | X20: =COUNTIF(B20:W20,1)+COUNTIF(B20:W20,"IC") -> 0 | Y20: =IF(COUNTIF(B20:W20,"M")>0,"N/A absence longue",IF(X20>=2,"Atteint","Sous objectif")) -> Sous objectif
A21: François L'Hostis | X21: =COUNTIF(B21:W21,1)+COUNTIF(B21:W21,"IC") -> 0 | Y21: =IF(COUNTIF(B21:W21,"M")>0,"N/A absence longue",IF(X21>=2,"Atteint","Sous objectif")) -> Sous objectif
A22: Barnabé Melaine | C22: 1 | N22: 1 | P22: 1 | T22: 1 | X22: =COUNTIF(B22:W22,1)+COUNTIF(B22:W22,"IC") -> 4 | Y22: =IF(COUNTIF(B22:W22,"M")>0,"N/A absence longue",IF(X22>=2,"Atteint","Sous objectif")) -> Atteint
A23: Anthony Mocaer | X23: =COUNTIF(B23:W23,1)+COUNTIF(B23:W23,"IC") -> 0 | Y23: =IF(COUNTIF(B23:W23,"M")>0,"N/A absence longue",IF(X23>=2,"Atteint","Sous objectif")) -> Sous objectif
A24: Esther Mussot | L24: 1 | T24: 1 | X24: =COUNTIF(B24:W24,1)+COUNTIF(B24:W24,"IC") -> 2 | Y24: =IF(COUNTIF(B24:W24,"M")>0,"N/A absence longue",IF(X24>=2,"Atteint","Sous objectif")) -> Atteint
A25: Florian Roudier | C25: 1 | T25: 1 | X25: =COUNTIF(B25:W25,1)+COUNTIF(B25:W25,"IC") -> 2 | Y25: =IF(COUNTIF(B25:W25,"M")>0,"N/A absence longue",IF(X25>=2,"Atteint","Sous objectif")) -> Atteint
A26: Sandra Tang | X26: =COUNTIF(B26:W26,1)+COUNTIF(B26:W26,"IC") -> 0 | Y26: =IF(COUNTIF(B26:W26,"M")>0,"N/A absence longue",IF(X26>=2,"Atteint","Sous objectif")) -> Sous objectif
A27: Mathieu Ultsch | F27: 1 | X27: =COUNTIF(B27:W27,1)+COUNTIF(B27:W27,"IC") -> 1 | Y27: =IF(COUNTIF(B27:W27,"M")>0,"N/A absence longue",IF(X27>=2,"Atteint","Sous objectif")) -> Sous objectif
A28: Amandine Ziegler | X28: =COUNTIF(B28:W28,1)+COUNTIF(B28:W28,"IC") -> 0 | Y28: =IF(COUNTIF(B28:W28,"M")>0,"N/A absence longue",IF(X28>=2,"Atteint","Sous objectif")) -> Sous objectif
A30: — Événements —
A31: XO Day
A32: XO Product Day
A33: Séminaire

Sheet Formations
A1: Catalogue des sessions de formation
A3: id_session | B3: date | C3: thématique | D3: formateur | E3: lien_support
A4: F-2025-001 | B4: 45720 | C4: Delivery - Essentiel - La gestion du Backlog Produit ​ | D4: Jérémie Kieffer
A5: F-2025-002 | B5: 45734 | C5: Rattrapage - Delivery - Essentiel - La gestion du Backlog Produit | D5: Florian Le Fur
A6: F-2025-003 | B6: 45783 | C6: Discovery - Essentiel - Comprendre la Discovery​ | D6: Jérémie Kieffer
A7: F-2025-004 | B7: 45792 | C7: Delivery - Essentiel - MVP & User Story Mapping​ | D7: Jérémie Kieffer
A8: F-2025-005 | B8: 45839 | C8: Product Expert - Essentiel - Initiation aux API : Fondamentaux et usages​ | D8: Simon Kerhyuel
A9: F-2025-006 | B9: 45869 | C9: Discovery - Essentiel - Comprendre la Discovery ​ Les différents frameworks | D9: Jérémie Kieffer
A10: F-2025-007 | B10: 45923 | C10: Discovery - Avancé - Identifier le bon problème et les bonnes cibles​ | D10: Jérémie Kieffer
A11: F-2025-008 | B11: 45951 | C11: Rattrapage - Avancé - Discovery - Identifier le bon problème et les bonnes cibles | D11: Jérémie Kieffer
A12: F-2025-009 | B12: 45993 | C12: IA - Essentiel - Module 1 - Intégrer l'IA et les LLM dans sa pratique de Product Manager | D12: Matthieu Le Corre, Anthony Mocaer
A13: F-2026-001 | B13: 46044 | C13: IA - Essentiel - Module 1 - Intégrer l'IA et les LLM dans sa pratique de Product Manager | D13: Matthieu Le Corre
A14: F-2026-002 | B14: 46049 | C14: Discovery - Avancé - Les protocoles de recherche utilisateurs​ | D14: Jérémie Kieffer
A15: F-2026-003 | B15: 46063 | C15: Product Expert - Essentiel - Initiation aux API : Fondamentaux et usages​ | D15: Simon Kerhyuel
... A23: F-2026-011 | B23: 46210 | C23: IA - Maîtriser les Skills Claude | D23: Matthieu Le Corre

Sheet Formations_Participations
A1: Participations aux sessions de formation
A3: Consultant | B3: Total | C3: F-2025-001 | D3: F-2025-002 | E3: F-2025-003 | F3: F-2025-004 | G3: F-2025-005 | H3: F-2025-006 | I3: F-2025-007 | J3: F-2025-008 | K3: F-2025-009 | L3: F-2026-001 | M3: F-2026-002 | N3: F-2026-003 | O3: F-2026-004 | P3: F-2026-005 | Q3: F-2026-006 | R3: F-2026-007 | S3: F-2026-008 | T3: F-2026-009 | U3: F-2026-010 | V3: F-2026-011
A4: Eva Andrzejewski | B4: =COUNTIF(C4:XFD4,"P")+COUNTIF(C4:XFD4,"F") -> 4 | O4: P | P4: P | T4: P | V4: P
A5: Zelal Aslan | B5: =COUNTIF(C5:XFD5,"P")+COUNTIF(C5:XFD5,"F") -> 2 | R5: P | S5: P
A6: Calixte Bailly | B6: =COUNTIF(C6:XFD6,"P")+COUNTIF(C6:XFD6,"F") -> 3 | F6: P | H6: P | S6: F
A7: Laureline Berthou | B7: =COUNTIF(C7:XFD7,"P")+COUNTIF(C7:XFD7,"F") -> 11 | D7: P | E7: P | G7: P | H7: P | I7: P | K7: P | M7: P | O7: P | P7: P | T7: P | U7: P
A8: Axel Charletoux | B8: =COUNTIF(C8:XFD8,"P")+COUNTIF(C8:XFD8,"F") -> 4 | D8: P | E8: P | K8: P | R8: P
A9: Matthieu Le Corre | B9: =COUNTIF(C9:XFD9,"P")+COUNTIF(C9:XFD9,"F") -> 13 | C9: P | F9: P | I9: P | J9: P | K9: F | L9: F | M9: P | N9: P | O9: F | P9: P | T9: P | U9: P | V9: F
A10: Geoffroy Debellabre | B10: =COUNTIF(C10:XFD10,"P")+COUNTIF(C10:XFD10,"F") -> 1 | U10: F
A11: Anthéa Delpuech | B11: =COUNTIF(C11:XFD11,"P")+COUNTIF(C11:XFD11,"F") -> 3 | L11: P | O11: P | S11: P
A12: Alexandre Dieulesaint | B12: =COUNTIF(C12:XFD12,"P")+COUNTIF(C12:XFD12,"F") -> 3 | R12: P | T12: P | V12: P
A13: Théo Esposito | B13: =COUNTIF(C13:XFD13,"P")+COUNTIF(C13:XFD13,"F") -> 5 | K13: P | P13: F | S13: F | U13: F | V13: P
A14: Florian Le Fur | B14: =COUNTIF(C14:XFD14,"P")+COUNTIF(C14:XFD14,"F") -> 7 | C14: P | D14: F | F14: P | G14: P | I14: P | S14: P | U14: P
A15: Vincent Girard | B15: =COUNTIF(C15:XFD15,"P")+COUNTIF(C15:XFD15,"F") -> 8 | K15: P | M15: P | N15: P | O15: P | P15: P | T15: P | U15: P | V15: P
A16: Félix Hantraye | B16: =COUNTIF(C16:XFD16,"P")+COUNTIF(C16:XFD16,"F") -> 6 | J16: P | K16: P | N16: P | R16: P | U16: P | V16: P
A17: Simon Kerhyuel | B17: =COUNTIF(C17:XFD17,"P")+COUNTIF(C17:XFD17,"F") -> 9 | D17: P | E17: P | G17: F | J17: P | K17: P | N17: F | R17: P | S17: P | T17: F
A18: Jérémie Kieffer | B18: =COUNTIF(C18:XFD18,"P")+COUNTIF(C18:XFD18,"F") -> 16 | C18: F | D18: P | E18: F | F18: F | G18: P | H18: F | I18: F | J18: F | L18: P | M18: F | O18: P | Q18: F | R18: P | S18: P | T18: P | U18: P
A19: François L'Hostis | B19: =COUNTIF(C19:XFD19,"P")+COUNTIF(C19:XFD19,"F") -> 6 | C19: P | E19: P | H19: P | O19: P | S19: P | V19: P
A20: Barnabé Melaine | B20: =COUNTIF(C20:XFD20,"P")+COUNTIF(C20:XFD20,"F") -> 4 | C20: P | I20: P | N20: P | P20: P
A21: Anthony Mocaer | B21: =COUNTIF(C21:XFD21,"P")+COUNTIF(C21:XFD21,"F") -> 5 | E21: P | F21: P | J21: P | K21: F | R21: F
A22: Esther Mussot | B22: =COUNTIF(C22:XFD22,"P")+COUNTIF(C22:XFD22,"F") -> 3 | Q22: P | U22: P | V22: P
A23: Florian Roudier | B23: =COUNTIF(C23:XFD23,"P")+COUNTIF(C23:XFD23,"F") -> 6 | D23: P | E23: P | F23: P | G23: P | H23: P | I23: P
A24: Sandra Tang | B24: =COUNTIF(C24:XFD24,"P")+COUNTIF(C24:XFD24,"F") -> 2 | S24: P | U24: P
A25: Mathieu Ultsch | B25: =COUNTIF(C25:XFD25,"P")+COUNTIF(C25:XFD25,"F") -> 8 | K25: P | M25: P | N25: P | O25: P | P25: P | Q25: P | T25: P | V25: P
A26: Amandine Ziegler | B26: =COUNTIF(C26:XFD26,"P")+COUNTIF(C26:XFD26,"F") -> 9 | C26: P | E26: P | H26: P | J26: P | K26: P | N26: P | O26: P | P26: P | Q26: P
A27: Anita Aladine | B27: =COUNTIF(C27:XFD27,"P")+COUNTIF(C27:XFD27,"F") -> 1 | H27: P
A28: Gaetan Le Bail | B28: =COUNTIF(C28:XFD28,"P")+COUNTIF(C28:XFD28,"F") -> 1 | D28: P
A29: Agnes Bregeon | B29: =COUNTIF(C29:XFD29,"P")+COUNTIF(C29:XFD29,"F") -> 2 | U29: P | V29: P
A30: Julien Calvao | B30: =COUNTIF(C30:XFD30,"P")+COUNTIF(C30:XFD30,"F") -> 8 | M30: P | N30: P | O30: P | P30: P | Q30: P | R30: P | S30: P | T30: P
A31: Camille Chansigaud | B31: =COUNTIF(C31:XFD31,"P")+COUNTIF(C31:XFD31,"F") -> 2 | C31: P | H31: P
A32: Caroline Hamoud | B32: =COUNTIF(C32:XFD32,"P")+COUNTIF(C32:XFD32,"F") -> 5 | E32: P | F32: P | M32: P | R32: P | U32: P
A33: Bertrand Mignot | B33: =COUNTIF(C33:XFD33,"P")+COUNTIF(C33:XFD33,"F") -> 5 | J33: P | M33: P | N33: P | O33: P | P33: P
A34: Melchior R | B34: =COUNTIF(C34:XFD34,"P")+COUNTIF(C34:XFD34,"F") -> 1 | H34: P
A35: Nicolas Renard | B35: =COUNTIF(C35:XFD35,"P")+COUNTIF(C35:XFD35,"F") -> 2 | E35: P | H35: P
A36: Emilien Rue | B36: =COUNTIF(C36:XFD36,"P")+COUNTIF(C36:XFD36,"F") -> 1 | D36: P
A37: Nacim Souni | B37: =COUNTIF(C37:XFD37,"P")+COUNTIF(C37:XFD37,"F") -> 1 | L37: P

Sheet Log
A1: Log — format long (alimentation automatique)
A3: Ce tableau consolide automatiquement les données de tous les onglets de saisie au format long (1 ligne = 1 jour × 1 consultant × 1 statut). C'est ce tableau qui est exporté en CSV pour alimenter le dashboard.
A5: Important : ne pas saisir manuellement dans cet onglet. Toute saisie se fait dans les onglets "Saisie YYYY-MM".
A7: Date | B7: Année-Mois | C7: Jour semaine | D7: Consultant | E7: Statut | F7: Source

Sheet Synthèse mensuelle
A1: Synthèse mensuelle — KPI agrégés
A3: Ces KPI sont calculés automatiquement depuis les onglets de saisie mensuelle.
A5: Mois | B5: Nb consultants | C5: Présences totales | D5: Atteinte OKR (%) | E5: Moyenne (j) | F5: Venus ≥1x | G5: Pic du mois
A6: Février 2026 | B6: =COUNTIF('Saisie 2026-02'!W4:W29,"Atteint")+COUNTIF('Saisie 2026-02'!W4:W29,"Sous objectif") -> 24 | C6: =SUM('Saisie 2026-02'!V4:V29) -> 73 | D6: =IFERROR(COUNTIF('Saisie 2026-02'!W4:W29,"Atteint")/(COUNTIF('Saisie 2026-02'!W4:W29,"Atteint")+COUNTIF('Saisie 2026-02'!W4:W29,"Sous objectif")),0) -> 0.625 | E6: =IFERROR(SUM('Saisie 2026-02'!V4:V29)/(COUNTIF('Saisie 2026-02'!W4:W29,"Atteint")+COUNTIF('Saisie 2026-02'!W4:W29,"Sous objectif")),0) -> 3.0416667 | F6: =COUNTIF('Saisie 2026-02'!V4:V29,">=1") -> 20 | G6: À calculer manuellement / via dashboard
A7: Mars 2026 | B7: =COUNTIF('Saisie 2026-03'!Y4:Y29,"Atteint")+COUNTIF('Saisie 2026-03'!Y4:Y29,"Sous objectif") -> 25 | C7: =SUM('Saisie 2026-03'!X4:X29) -> 72 | D7: =IFERROR(COUNTIF('Saisie 2026-03'!Y4:Y29,"Atteint")/(COUNTIF('Saisie 2026-03'!Y4:Y29,"Atteint")+COUNTIF('Saisie 2026-03'!Y4:Y29,"Sous objectif")),0) -> 0.6 | E7: =IFERROR(SUM('Saisie 2026-03'!X4:X29)/(COUNTIF('Saisie 2026-03'!Y4:Y29,"Atteint")+COUNTIF('Saisie 2026-03'!Y4:Y29,"Sous objectif")),0) -> 2.88 | F7: =COUNTIF('Saisie 2026-03'!X4:X29,">=1") -> 23 | G7: À calculer manuellement / via dashboard
A8: Avril 2026 | B8: =COUNTIF('Saisie 2026-04'!Y4:Y29,"Atteint")+COUNTIF('Saisie 2026-04'!Y4:Y29,"Sous objectif") -> 26 | C8: =SUM('Saisie 2026-04'!X4:X29) -> 82 | D8: =IFERROR(COUNTIF('Saisie 2026-04'!Y4:Y29,"Atteint")/(COUNTIF('Saisie 2026-04'!Y4:Y29,"Atteint")+COUNTIF('Saisie 2026-04'!Y4:Y29,"Sous objectif")),0) -> 0.84615385 | E8: =IFERROR(SUM('Saisie 2026-04'!X4:X29)/(COUNTIF('Saisie 2026-04'!Y4:Y29,"Atteint")+COUNTIF('Saisie 2026-04'!Y4:Y29,"Sous objectif")),0) -> 3.1538462 | F8: =COUNTIF('Saisie 2026-04'!X4:X29,">=1") -> 26 | G8: À calculer manuellement / via dashboard
A9: Mai 2026 | B9: =COUNTIF('Saisie 2026-05'!U4:U29,"Atteint")+COUNTIF('Saisie 2026-05'!U4:U29,"Sous objectif") -> 26 | C9: =SUM('Saisie 2026-05'!T4:T29) -> 81 | D9: =IFERROR(COUNTIF('Saisie 2026-05'!U4:U29,"Atteint")/(COUNTIF('Saisie 2026-05'!U4:U29,"Atteint")+COUNTIF('Saisie 2026-05'!U4:U29,"Sous objectif")),0) -> 0.53846154 | E9: =IFERROR(SUM('Saisie 2026-05'!T4:T29)/(COUNTIF('Saisie 2026-05'!U4:U29,"Atteint")+COUNTIF('Saisie 2026-05'!U4:U29,"Sous objectif")),0) -> 3.1153846 | F9: =COUNTIF('Saisie 2026-05'!T4:T29,">=1") -> 24 | G9: À calculer manuellement / via dashboard
A10: Juin 2026 | B10: =COUNTIF('Saisie 2026-06'!Y4:Y30,"Atteint")+COUNTIF('Saisie 2026-06'!Y4:Y30,"Sous objectif") -> 27 | C10: =SUM('Saisie 2026-06'!X4:X30) -> 111 | D10: =IFERROR(COUNTIF('Saisie 2026-06'!Y4:Y30,"Atteint")/(COUNTIF('Saisie 2026-06'!Y4:Y30,"Atteint")+COUNTIF('Saisie 2026-06'!Y4:Y30,"Sous objectif")),0) -> 0.77777778 | E10: =IFERROR(SUM('Saisie 2026-06'!X4:X30)/(COUNTIF('Saisie 2026-06'!Y4:Y30,"Atteint")+COUNTIF('Saisie 2026-06'!Y4:Y30,"Sous objectif")),0) -> 4.1111111 | F10: =COUNTIF('Saisie 2026-06'!X4:X30,">=1") -> 25 | G10: À calculer manuellement / via dashboard
A11: Moyenne T2 | B11: =AVERAGE(B8:B10) -> 26.333333 | C11: =AVERAGE(C8:C10) -> 91.333333 | D11: =AVERAGE(D8:D10) -> 0.72079772 | E11: =AVERAGE(E8:E10) -> 3.460114 | F11: =AVERAGE(F8:F10) -> 25

Sheet Synthèse consultant
A1: Synthèse par consultant — vue trimestrielle
A3: Vue par consultant : présences et statut OKR par mois (févr.→juin), plus régularité sur la période.
A5: Consultant | B5: Févr. 2026 | C5: Mars 2026 | D5: Avr. 2026 | E5: Mai 2026 | F5: Juin 2026 | G5: Mois ≥2j | H5: Régularité
A6: Eva Andrzejewski | B6: =IF('Saisie 2026-02'!W4="N/A absence longue","M",'Saisie 2026-02'!V4) -> 3 | C6: =IF('Saisie 2026-03'!Y4="N/A absence longue","M",'Saisie 2026-03'!X4) -> 3 | D6: =IF('Saisie 2026-04'!Y4="N/A absence longue","M",'Saisie 2026-04'!X4) -> 2 | E6: =IF('Saisie 2026-05'!U4="N/A absence longue","M",'Saisie 2026-05'!T4) -> 3 | F6: =IF('Saisie 2026-06'!Y4="N/A absence longue","M",'Saisie 2026-06'!X4) -> 2 | G6: =COUNTIF(B6:F6,">=2") -> 5 | H6: =IF(G6=5,"5/5 ✓",IF(G6=0,"0/5 ⚠⚠",IF(G6<=1,G6&"/5 ⚠",G6&"/5"))) -> 5/5 ✓
A7: Zelal Aslan | B7: =IF('Saisie 2026-02'!W5="N/A absence longue","M",'Saisie 2026-02'!V5) -> M | C7: =IF('Saisie 2026-03'!Y5="N/A absence longue","M",'Saisie 2026-03'!X5) -> M | D7: =IF('Saisie 2026-04'!Y5="N/A absence longue","M",'Saisie 2026-04'!X5) -> 11 | E7: =IF('Saisie 2026-05'!U5="N/A absence longue","M",'Saisie 2026-05'!T5) -> 8 | F7: =IF('Saisie 2026-06'!Y5="N/A absence longue","M",'Saisie 2026-06'!X5) -> 9 | G7: =COUNTIF(B7:F7,">=2") -> 3 | H7: =IF(G7=5,"5/5 ✓",IF(G7=0,"0/5 ⚠⚠",IF(G7<=1,G7&"/5 ⚠",G7&"/5"))) -> 3/5
A8: Calixte Bailly | B8: =IF('Saisie 2026-02'!W6="N/A absence longue","M",'Saisie 2026-02'!V6) -> 1 | C8: =IF('Saisie 2026-03'!Y6="N/A absence longue","M",'Saisie 2026-03'!X6) -> 0 | D8: =IF('Saisie 2026-04'!Y6="N/A absence longue","M",'Saisie 2026-04'!X6) -> 1 | E8: =IF('Saisie 2026-05'!U6="N/A absence longue","M",'Saisie 2026-05'!T6) -> 1 | F8: =IF('Saisie 2026-06'!Y6="N/A absence longue","M",'Saisie 2026-06'!X6) -> 1 | G8: =COUNTIF(B8:F8,">=2") -> 0 | H8: =IF(G8=5,"5/5 ✓",IF(G8=0,"0/5 ⚠⚠",IF(G8<=1,G8&"/5 ⚠",G8&"/5"))) -> 0/5 ⚠⚠
A9: Laureline Berthou | B9: =IF('Saisie 2026-02'!W7="N/A absence longue","M",'Saisie 2026-02'!V7) -> 5 | C9: =IF('Saisie 2026-03'!Y7="N/A absence longue","M",'Saisie 2026-03'!X7) -> 6 | D9: =IF('Saisie 2026-04'!Y7="N/A absence longue","M",'Saisie 2026-04'!X7) -> 4 | E9: =IF('Saisie 2026-05'!U7="N/A absence longue","M",'Saisie 2026-05'!T7) -> 5 | F9: =IF('Saisie 2026-06'!Y7="N/A absence longue","M",'Saisie 2026-06'!X7) -> 7 | G9: =COUNTIF(B9:F9,">=2") -> 5 | H9: =IF(G9=5,"5/5 ✓",IF(G9=0,"0/5 ⚠⚠",IF(G9<=1,G9&"/5 ⚠",G9&"/5"))) -> 5/5 ✓
A10: Julien Calvao | B10: =IF('Saisie 2026-02'!W8="N/A absence longue","M",'Saisie 2026-02'!V8) -> 11 | C10: =IF('Saisie 2026-03'!Y8="N/A absence longue","M",'Saisie 2026-03'!X8) -> 12 | D10: =IF('Saisie 2026-04'!Y8="N/A absence longue","M",'Saisie 2026-04'!X8) -> 12 | E10: =IF('Saisie 2026-05'!U8="N/A absence longue","M",'Saisie 2026-05'!T8) -> 11 | F10: =IF('Saisie 2026-06'!Y9="N/A absence longue","M",'Saisie 2026-06'!X9) -> 2 | G10: =COUNTIF(B10:F10,">=2") -> 5 | H10: =IF(G10=5,"5/5 ✓",IF(G10=0,"0/5 ⚠⚠",IF(G10<=1,G10&"/5 ⚠",G10&"/5"))) -> 5/5 ✓
A11: Axel Charletoux | B11: =IF('Saisie 2026-02'!W9="N/A absence longue","M",'Saisie 2026-02'!V9) -> 1 | C11: =IF('Saisie 2026-03'!Y9="N/A absence longue","M",'Saisie 2026-03'!X9) -> 1 | D11: =IF('Saisie 2026-04'!Y9="N/A absence longue","M",'Saisie 2026-04'!X9) -> 2 | E11: =IF('Saisie 2026-05'!U9="N/A absence longue","M",'Saisie 2026-05'!T9) -> 10 | F11: =IF('Saisie 2026-06'!Y10="N/A absence longue","M",'Saisie 2026-06'!X10) -> 3 | G11: =COUNTIF(B11:F11,">=2") -> 3 | H11: =IF(G11=5,"5/5 ✓",IF(G11=0,"0/5 ⚠⚠",IF(G11<=1,G11&"/5 ⚠",G11&"/5"))) -> 3/5
A12: Geoffroy Debellabre | B12: =IF('Saisie 2026-02'!W10="N/A absence longue","M",'Saisie 2026-02'!V10) -> 8 | C12: =IF('Saisie 2026-03'!Y10="N/A absence longue","M",'Saisie 2026-03'!X10) -> 7 | D12: =IF('Saisie 2026-04'!Y10="N/A absence longue","M",'Saisie 2026-04'!X10) -> 6 | E12: =IF('Saisie 2026-05'!U10="N/A absence longue","M",'Saisie 2026-05'!T10) -> 6 | F12: =IF('Saisie 2026-06'!Y11="N/A absence longue","M",'Saisie 2026-06'!X11) -> 8 | G12: =COUNTIF(B12:F12,">=2") -> 5 | H12: =IF(G12=5,"5/5 ✓",IF(G12=0,"0/5 ⚠⚠",IF(G12<=1,G12&"/5 ⚠",G12&"/5"))) -> 5/5 ✓
A13: Anthéa Delpuech | B13: =IF('Saisie 2026-02'!W11="N/A absence longue","M",'Saisie 2026-02'!V11) -> 0 | C13: =IF('Saisie 2026-03'!Y11="N/A absence longue","M",'Saisie 2026-03'!X11) -> 2 | D13: =IF('Saisie 2026-04'!Y11="N/A absence longue","M",'Saisie 2026-04'!X11) -> 2 | E13: =IF('Saisie 2026-05'!U11="N/A absence longue","M",'Saisie 2026-05'!T11) -> 1 | F13: =IF('Saisie 2026-06'!Y12="N/A absence longue","M",'Saisie 2026-06'!X12) -> 2 | G13: =COUNTIF(B13:F13,">=2") -> 3 | H13: =IF(G13=5,"5/5 ✓",IF(G13=0,"0/5 ⚠⚠",IF(G13<=1,G13&"/5 ⚠",G13&"/5"))) -> 3/5
A14: Alexandre Dieulesaint | B14: =IF('Saisie 2026-02'!W12="N/A absence longue","M",'Saisie 2026-02'!V12) -> 4 | C14: =IF('Saisie 2026-03'!Y12="N/A absence longue","M",'Saisie 2026-03'!X12) -> 1 | D14: =IF('Saisie 2026-04'!Y12="N/A absence longue","M",'Saisie 2026-04'!X12) -> 1 | E14: =IF('Saisie 2026-05'!U12="N/A absence longue","M",'Saisie 2026-05'!T12) -> 1 | F14: =IF('Saisie 2026-06'!Y13="N/A absence longue","M",'Saisie 2026-06'!X13) -> 2 | G14: =COUNTIF(B14:F14,">=2") -> 2 | H14: =IF(G14=5,"5/5 ✓",IF(G14=0,"0/5 ⚠⚠",IF(G14<=1,G14&"/5 ⚠",G14&"/5"))) -> 2/5
A15: Théo Esposito | B15: =IF('Saisie 2026-02'!W13="N/A absence longue","M",'Saisie 2026-02'!V13) -> 0 | C15: =IF('Saisie 2026-03'!Y13="N/A absence longue","M",'Saisie 2026-03'!X13) -> 2 | D15: =IF('Saisie 2026-04'!Y13="N/A absence longue","M",'Saisie 2026-04'!X13) -> 1 | E15: =IF('Saisie 2026-05'!U13="N/A absence longue","M",'Saisie 2026-05'!T13) -> 1 | F15: =IF('Saisie 2026-06'!Y14="N/A absence longue","M",'Saisie 2026-06'!X14) -> 2 | G15: =COUNTIF(B15:F15,">=2") -> 2 | H15: =IF(G15=5,"5/5 ✓",IF(G15=0,"0/5 ⚠⚠",IF(G15<=1,G15&"/5 ⚠",G15&"/5"))) -> 2/5
A16: Vincent Girard | B16: =IF('Saisie 2026-02'!W14="N/A absence longue","M",'Saisie 2026-02'!V14) -> 3 | C16: =IF('Saisie 2026-03'!Y14="N/A absence longue","M",'Saisie 2026-03'!X14) -> 2 | D16: =IF('Saisie 2026-04'!Y14="N/A absence longue","M",'Saisie 2026-04'!X14) -> 2 | E16: =IF('Saisie 2026-05'!U14="N/A absence longue","M",'Saisie 2026-05'!T14) -> 1 | F16: =IF('Saisie 2026-06'!Y15="N/A absence longue","M",'Saisie 2026-06'!X15) -> 3 | G16: =COUNTIF(B16:F16,">=2") -> 4 | H16: =IF(G16=5,"5/5 ✓",IF(G16=0,"0/5 ⚠⚠",IF(G16<=1,G16&"/5 ⚠",G16&"/5"))) -> 4/5
A17: Caroline Hamoud | B17: =IF('Saisie 2026-02'!W15="N/A absence longue","M",'Saisie 2026-02'!V15) -> 2 | C17: =IF('Saisie 2026-03'!Y15="N/A absence longue","M",'Saisie 2026-03'!X15) -> 5 | D17: =IF('Saisie 2026-04'!Y15="N/A absence longue","M",'Saisie 2026-04'!X15) -> 4 | E17: =IF('Saisie 2026-05'!U15="N/A absence longue","M",'Saisie 2026-05'!T15) -> 3 | F17: =IF('Saisie 2026-06'!Y16="N/A absence longue","M",'Saisie 2026-06'!X16) -> 6 | G17: =COUNTIF(B17:F17,">=2") -> 5 | H17: =IF(G17=5,"5/5 ✓",IF(G17=0,"0/5 ⚠⚠",IF(G17<=1,G17&"/5 ⚠",G17&"/5"))) -> 5/5 ✓
A18: Félix Hantraye | B18: =IF('Saisie 2026-02'!W16="N/A absence longue","M",'Saisie 2026-02'!V16) -> 3 | C18: =IF('Saisie 2026-03'!Y16="N/A absence longue","M",'Saisie 2026-03'!X16) -> 4 | D18: =IF('Saisie 2026-04'!Y16="N/A absence longue","M",'Saisie 2026-04'!X16) -> 2 | E18: =IF('Saisie 2026-05'!U16="N/A absence longue","M",'Saisie 2026-05'!T16) -> 3 | F18: =IF('Saisie 2026-06'!Y17="N/A absence longue","M",'Saisie 2026-06'!X17) -> 2 | G18: =COUNTIF(B18:F18,">=2") -> 5 | H18: =IF(G18=5,"5/5 ✓",IF(G18=0,"0/5 ⚠⚠",IF(G18<=1,G18&"/5 ⚠",G18&"/5"))) -> 5/5 ✓
A19: Simon Kerhyuel | B19: =IF('Saisie 2026-02'!W17="N/A absence longue","M",'Saisie 2026-02'!V17) -> 0 | C19: =IF('Saisie 2026-03'!Y17="N/A absence longue","M",'Saisie 2026-03'!X17) -> 1 | D19: =IF('Saisie 2026-04'!Y17="N/A absence longue","M",'Saisie 2026-04'!X17) -> 3 | E19: =IF('Saisie 2026-05'!U17="N/A absence longue","M",'Saisie 2026-05'!T17) -> 8 | F19: =IF('Saisie 2026-06'!Y18="N/A absence longue","M",'Saisie 2026-06'!X18) -> 13 | G19: =COUNTIF(B19:F19,">=2") -> 3 | H19: =IF(G19=5,"5/5 ✓",IF(G19=0,"0/5 ⚠⚠",IF(G19<=1,G19&"/5 ⚠",G19&"/5"))) -> 3/5
A20: Matthieu Le Corre | B20: =IF('Saisie 2026-02'!W18="N/A absence longue","M",'Saisie 2026-02'!V18) -> 3 | C20: =IF('Saisie 2026-03'!Y18="N/A absence longue","M",'Saisie 2026-03'!X18) -> 1 | D20: =IF('Saisie 2026-04'!Y18="N/A absence longue","M",'Saisie 2026-04'!X18) -> 2 | E20: =IF('Saisie 2026-05'!U18="N/A absence longue","M",'Saisie 2026-05'!T18) -> 1 | F20: =IF('Saisie 2026-06'!Y19="N/A absence longue","M",'Saisie 2026-06'!X19) -> 3 | G20: =COUNTIF(B20:F20,">=2") -> 3 | H20: =IF(G20=5,"5/5 ✓",IF(G20=0,"0/5 ⚠⚠",IF(G20<=1,G20&"/5 ⚠",G20&"/5"))) -> 3/5
A21: Florian Le Fur | B21: =IF('Saisie 2026-02'!W19="N/A absence longue","M",'Saisie 2026-02'!V19) -> 1 | C21: =IF('Saisie 2026-03'!Y19="N/A absence longue","M",'Saisie 2026-03'!X19) -> 1 | D21: =IF('Saisie 2026-04'!Y19="N/A absence longue","M",'Saisie 2026-04'!X19) -> 3 | E21: =IF('Saisie 2026-05'!U19="N/A absence longue","M",'Saisie 2026-05'!T19) -> 2 | F21: =IF('Saisie 2026-06'!Y20="N/A absence longue","M",'Saisie 2026-06'!X20) -> 1 | G21: =COUNTIF(B21:F21,">=2") -> 2 | H21: =IF(G21=5,"5/5 ✓",IF(G21=0,"0/5 ⚠⚠",IF(G21<=1,G21&"/5 ⚠",G21&"/5"))) -> 2/5
